<?xml version="1.0"?>
<robot xmlns:xacro="http://www.ros.org/wiki/xacro">

  <xacro:include filename="$(find tr3_description)/urdf/base/base.gazebo.xacro" />
	<xacro:include filename="$(find tr3_description)/urdf/base/base.transmission.xacro" />

	<!-- wheel macros -->
  <xacro:macro name="tr3_wheel" params="name *origin *axis">
		<joint name="${name}" type="continuous">
			<parent link="base_link"/>
			<child link="link_${name}"/>
			<xacro:insert_block name="axis" />
			<limit effort="100.0" velocity="8.8"/>
			<xacro:insert_block name="origin" />
    	<dynamics damping="0.001" friction="0.001"/>
		</joint>
		<link name="link_${name}">
			<collision>
				<geometry>
		      <mesh filename="package://tr3_description/meshes/stl/xt-wl-a.stl" scale="0.001 0.001 0.001"/>
				</geometry>
				<origin rpy="0 0 0" />
			</collision>
			<inertial>
      	<mass value="0.01" />
		    <inertia ixx="0.001" ixy="0.0" ixz="0.0" iyy="0.001" iyz="0.0" izz="0.001" />
				</inertial>
			<visual>
				<geometry>
		      <mesh filename="package://tr3_description/meshes/stl/xt-wl-a.stl" scale="0.001 0.001 0.001"/>
				</geometry>
		    <material name="slate_gray">
		      <color rgba="0.2 0.2 0.2 1"/>
		    </material>
				<origin rpy="0 0 0" />
			</visual>
		</link>
	</xacro:macro>

	<!-- resulting links and joints -->
	<link name="base_link">
		<collision>
			<geometry>
        <mesh filename="package://tr3_description/meshes/stl/tr-bs-a.stl" scale="0.001 0.001 0.001"/>
			</geometry>
			<origin rpy="0 0 3.1415" />
		</collision>
		<inertial>
      	<mass value="1" />
        <origin xyz="0 -0.300 0" />
		    <inertia ixx="0.001" ixy="0.0" ixz="0.0" iyy="0.001" iyz="0.0" izz="0.001" />
		</inertial>
		<visual>
			<geometry>
        <mesh filename="package://tr3_description/meshes/stl/tr-bs-a.stl" scale="0.001 0.001 0.001"/>
			</geometry>
      <material name="slate_gray">
        <color rgba="0.2 0.2 0.2 1"/>
      </material>
			<origin rpy="0 0 3.1415" />
		</visual>
	</link>

  <link name="link_b2">
    <collision>
      <geometry>
        <mesh filename="package://tr3_description/meshes/stl/tr-bs-b.stl" scale="0.001 0.001 0.001"/>
      </geometry>
      <origin rpy="0 0 1.5708" />
    </collision>
    <inertial>
        <mass value="0.01" />
        <inertia ixx="0.001" ixy="0.0" ixz="0.0" iyy="0.001" iyz="0.0" izz="0.001" />
    </inertial>
    <visual>
      <geometry>
        <mesh filename="package://tr3_description/meshes/stl/tr-bs-b.stl" scale="0.001 0.001 0.001"/>
      </geometry>
      <material name="slate_gray">
        <color rgba="0.2 0.2 0.2 1"/>
      </material>
      <origin rpy="0 0 1.5708" />
    </visual>
  </link>

  <link name="link_b3">
    <collision>
      <geometry>
        <mesh filename="package://tr3_description/meshes/stl/tr-bs-c.stl" scale="0.001 0.001 0.001"/>
      </geometry>
      <origin rpy="0 0 1.5708" />
    </collision>
    <inertial>
        <mass value="0.01" />
        <inertia ixx="0.001" ixy="0.0" ixz="0.0" iyy="0.001" iyz="0.0" izz="0.001" />
    </inertial>
    <visual>
      <geometry>
        <mesh filename="package://tr3_description/meshes/stl/tr-bs-c.stl" scale="0.001 0.001 0.001"/>
      </geometry>
      <material name="slate_gray">
        <color rgba="0.2 0.2 0.2 1"/>
      </material>
      <origin rpy="0 0 1.5708" />
    </visual>
  </link>

  <link name="link_b4">
    <collision>
      <geometry>
        <mesh filename="package://tr3_description/meshes/stl/tr-bs-b.stl" scale="0.001 0.001 0.001"/>
      </geometry>
      <origin rpy="0 0 1.5708" />
    </collision>
    <inertial>
        <mass value="0.01" />
        <inertia ixx="0.001" ixy="0.0" ixz="0.0" iyy="0.001" iyz="0.0" izz="0.001" />
    </inertial>
    <visual>
      <geometry>
        <mesh filename="package://tr3_description/meshes/stl/tr-bs-b.stl" scale="0.001 0.001 0.001"/>
      </geometry>
      <material name="slate_gray">
        <color rgba="0.2 0.2 0.2 1"/>
      </material>
      <origin rpy="0 0 1.5708" />
    </visual>
  </link>

  <link name="link_b5">
    <collision>
      <geometry>
        <mesh filename="package://tr3_description/meshes/stl/tr-bs-c.stl" scale="0.001 0.001 0.001"/>
      </geometry>
      <origin rpy="0 0 1.5708" />
    </collision>
    <inertial>
        <mass value="0.01" />
        <inertia ixx="0.001" ixy="0.0" ixz="0.0" iyy="0.001" iyz="0.0" izz="0.001" />
    </inertial>
    <visual>
      <geometry>
        <mesh filename="package://tr3_description/meshes/stl/tr-bs-c.stl" scale="0.001 0.001 0.001"/>
      </geometry>
      <material name="slate_gray">
        <color rgba="0.2 0.2 0.2 1"/>
      </material>
      <origin rpy="0 0 1.5708" />
    </visual>
  </link>

  <joint name="b2" type="continuous">
    <parent link="base_link"/>
    <child link="link_b2"/>
    <origin xyz="-0.147 -0.39975 -0.09635" rpy="0 3.1415 -1.5708"/>
    <axis xyz="0 0 1"/>
    <dynamics damping="0.1" friction="0.1"/>
  </joint>

  <joint name="b3" type="continuous">
    <parent link="link_b2"/>
    <child link="link_b3"/>
    <origin xyz="-0.0138 0 0.0390" rpy="1.5708 0 0"/>
    <axis xyz="0 0 1"/>
    <dynamics damping="0.1" friction="0.1"/>
  </joint>

  <joint name="b4" type="continuous">
    <parent link="base_link"/>
    <child link="link_b4"/>
    <origin xyz="0.147 -0.39975 -0.09635" rpy="0 3.1415 -1.5708"/>
    <axis xyz="0 0 1"/>
    <dynamics damping="0.1" friction="0.1"/>
  </joint>

  <joint name="b5" type="continuous">
    <parent link="link_b4"/>
    <child link="link_b5"/>
    <origin xyz="-0.0138 0 0.0390" rpy="1.5708 0 0"/>
    <axis xyz="0 0 1"/>
    <dynamics damping="0.1" friction="0.1"/>
  </joint>

  <joint name="rplidar_joint" type="fixed">
    <axis xyz="0 0 1" />
    <origin xyz="0 0.11 0" rpy="0 0 0" />
    <parent link="base_link" />
    <child link="laser" />
  </joint>

  <link name="laser">
  </link>

	<xacro:tr3_wheel name="b0">
    <axis xyz="0 -1 0"/>
		<origin rpy="0 0 -1.5708" xyz="0.3281 0 0"/>
	</xacro:tr3_wheel>

	<xacro:tr3_wheel name="b1">
    <axis xyz="0 1 0"/>
		<origin rpy="0 0 1.5708" xyz="-0.3281 0 0"/>
	</xacro:tr3_wheel>

</robot>
