<?xml version="1.0"?>
<robot xmlns:xacro="http://www.ros.org/wiki/xacro">

  <xacro:include filename="$(find tr3_description)/urdf/head/head.gazebo.xacro" />
	<xacro:include filename="$(find tr3_description)/urdf/head/head.transmission.xacro" />

	<link name="neck_link">
		<collision>
			<geometry>
        <mesh filename="package://tr3_description/meshes/stl/xt-hd-a.stl" scale="0.001 0.001 0.001"/>
			</geometry>
			<origin rpy="1.5708 0 1.5708"/>
		</collision>
		<inertial>
			<mass value="0.005"/>
			<inertia ixx="0.001" iyy="0.001" izz="0.001" ixy="0" ixz="0" iyz="0" />
		</inertial>
		<visual>
			<geometry>
        <mesh filename="package://tr3_description/meshes/stl/xt-hd-a.stl" scale="0.001 0.001 0.001"/>
			</geometry>
	    <material name="slate_gray">
	      <color rgba="0.2 0.2 0.2 1"/>
	    </material>
			<origin rpy="1.5708 0 1.5708"/>
		</visual>
	</link>

	<link name="head_link">
		<collision>
			<geometry>
        <mesh filename="package://tr3_description/meshes/stl/xt-hd-b.stl" scale="0.001 0.001 0.001"/>
			</geometry>
			<origin rpy="0 -1.5708 1.5708"/>
		</collision>
		<inertial>
			<mass value="0.005"/>
			<inertia ixx="0.001" iyy="0.001" izz="0.001" ixy="0" ixz="0" iyz="0" />
		</inertial>
		<visual>
			<geometry>
        <mesh filename="package://tr3_description/meshes/stl/xt-hd-b.stl" scale="0.001 0.001 0.001"/>
			</geometry>
	    <material name="slate_gray">
	      <color rgba="0.2 0.2 0.2 1"/>
	    </material>
			<origin rpy="0 -1.5708 1.5708"/>
		</visual>
	</link>

  <link name="camera_link">
    <collision>
      <origin xyz="0 0 0" rpy="0 0 0" />
      <geometry>
				<box size="0.01 0.01 0.01" />
      </geometry>
    </collision>
    <inertial>
      <mass value="0.00001" />
      <inertia ixx="0.0001" ixy="0" ixz="0" iyy="0.0001" iyz="0" izz="0.0001" />
    </inertial>
  </link>

  <link name="camera_link_optical">
  </link>

  <joint name="camera_optical_joint" type="fixed">
    <origin xyz="0 0 0" rpy="-1.5708 0 0"/>
    <parent link="camera_link"/>
    <child link="camera_link_optical"/>
  </joint>

	<joint name="camera_joint" type="fixed">
		<parent link="head_link"/>
		<child link="camera_link"/>
		<origin rpy="0 0 3.1415" xyz="-0.105 -0.145 0.085"/>
	</joint>

	<joint name="h0" type="revolute">
		<parent link="base_link"/>
		<child link="neck_link"/>
		<origin xyz="-0.3579 0 0.70325" rpy="0 0 1.5708" />
    <axis xyz="0 0 1"/>
		<limit effort="100.0" lower="-15" upper="15" velocity="0.20"/>
    <dynamics damping="0.1" friction="0.1"/>
	</joint>

	<joint name="h1" type="revolute">
		<parent link="neck_link"/>
		<child link="head_link"/>
		<origin xyz="0.067 -0.16617 0.24917" rpy="0 0 0"/>
    <axis xyz="-1 0 0"/>
		<limit effort="100.0" lower="-15" upper="15" velocity="0.20"/>
    <dynamics damping="0.1" friction="0.1"/>
	</joint>

</robot>
